Fehler in Elasticsearch: Unexpected token END OF FILE at position 2081.
ok
ok
^CTraceback (most recent call last):
  File "/usr/lib/python3/dist-packages/urllib3/connectionpool.py", line 377, in _make_request
    httplib_response = conn.getresponse(buffering=True)
TypeError: getresponse() got an unexpected keyword argument 'buffering'

During handling of the above exception, another exception occurred:

Traceback (most recent call last):
  File "/usr/lib/python3/dist-packages/urllib3/connectionpool.py", line 560, in urlopen
    body=body, headers=headers)
  File "/usr/lib/python3/dist-packages/urllib3/connectionpool.py", line 379, in _make_request
    httplib_response = conn.getresponse()
  File "/usr/lib/python3.5/http/client.py", line 1197, in getresponse
    response.begin()
  File "/usr/lib/python3.5/http/client.py", line 297, in begin
    version, status, reason = self._read_status()
  File "/usr/lib/python3.5/http/client.py", line 266, in _read_status
    raise RemoteDisconnected("Remote end closed connection without"
http.client.RemoteDisconnected: Remote end closed connection without response

During handling of the above exception, another exception occurred:

Traceback (most recent call last):
  File "/usr/lib/python3/dist-packages/requests/adapters.py", line 376, in send
    timeout=timeout
  File "/usr/lib/python3/dist-packages/urllib3/connectionpool.py", line 610, in urlopen
    _stacktrace=sys.exc_info()[2])
  File "/usr/lib/python3/dist-packages/urllib3/util/retry.py", line 247, in increment
    raise six.reraise(type(error), error, _stacktrace)
  File "/usr/lib/python3/dist-packages/six.py", line 685, in reraise
    raise value.with_traceback(tb)
  File "/usr/lib/python3/dist-packages/urllib3/connectionpool.py", line 560, in urlopen
    body=body, headers=headers)
  File "/usr/lib/python3/dist-packages/urllib3/connectionpool.py", line 379, in _make_request
    httplib_response = conn.getresponse()
  File "/usr/lib/python3.5/http/client.py", line 1197, in getresponse
    response.begin()
  File "/usr/lib/python3.5/http/client.py", line 297, in begin
    version, status, reason = self._read_status()
  File "/usr/lib/python3.5/http/client.py", line 266, in _read_status
    raise RemoteDisconnected("Remote end closed connection without"
requests.packages.urllib3.exceptions.ProtocolError: ('Connection aborted.', RemoteDisconnected('Remote end closed connection without response',))

During handling of the above exception, another exception occurred:

Traceback (most recent call last):
  File "/home/geislemx/middleware/classes/http_service.py", line 190, in call
    Response = self.__Session.send(ToSend)
  File "/usr/lib/python3/dist-packages/requests/sessions.py", line 576, in send
    r = adapter.send(request, **kwargs)
  File "/usr/lib/python3/dist-packages/requests/adapters.py", line 426, in send
    raise ConnectionError(err, request=request)
requests.exceptions.ConnectionError: ('Connection aborted.', RemoteDisconnected('Remote end closed connection without response',))

During handling of the above exception, another exception occurred:

Traceback (most recent call last):
  File "testServiceServer.py", line 25, in <module>
    print(Test.insertIntoDatabase(store, {'type':'document'}))
  File "/home/geislemx/middleware/classes/services.py", line 285, in insertIntoDatabase
    Response = self.__Database.insert(JSON, AdditionalParameter)
  File "/home/geislemx/middleware/classes/services.py", line 194, in insert
    raise e
  File "/home/geislemx/middleware/classes/services.py", line 191, in insert
    Response = self.__withOrWithoutBody(self.__Configuration['insert']['method'], Insert, self.__Insert, AdditionalParameter)
  File "/home/geislemx/middleware/classes/services.py", line 167, in __withOrWithoutBody
    Response = self.__withBody(ToDo, HTTPObject, AdditionalParameter)
  File "/home/geislemx/middleware/classes/services.py", line 149, in __withBody
    return HttpObject.call()
  File "/home/geislemx/middleware/classes/http_service.py", line 192, in call
    raise HttpServiceException(HttpServiceException.NO_CONECTION)
classes.http_service.HttpServiceException: 'The connection is not established'

During handling of the above exception, another exception occurred:

Traceback (most recent call last):
  File "/usr/lib/python3/dist-packages/urllib3/connectionpool.py", line 377, in _make_request
    httplib_response = conn.getresponse(buffering=True)
TypeError: getresponse() got an unexpected keyword argument 'buffering'

During handling of the above exception, another exception occurred:

Traceback (most recent call last):
  File "testServiceServer.py", line 28, in <module>
    print(Test.insertIntoDatabase(store, {'type':'document'}))
  File "/home/geislemx/middleware/classes/services.py", line 285, in insertIntoDatabase
    Response = self.__Database.insert(JSON, AdditionalParameter)
  File "/home/geislemx/middleware/classes/services.py", line 191, in insert
    Response = self.__withOrWithoutBody(self.__Configuration['insert']['method'], Insert, self.__Insert, AdditionalParameter)
  File "/home/geislemx/middleware/classes/services.py", line 167, in __withOrWithoutBody
    Response = self.__withBody(ToDo, HTTPObject, AdditionalParameter)
  File "/home/geislemx/middleware/classes/services.py", line 149, in __withBody
    return HttpObject.call()
  File "/home/geislemx/middleware/classes/http_service.py", line 190, in call
    Response = self.__Session.send(ToSend)
  File "/usr/lib/python3/dist-packages/requests/sessions.py", line 576, in send
    r = adapter.send(request, **kwargs)
  File "/usr/lib/python3/dist-packages/requests/adapters.py", line 376, in send
    timeout=timeout
  File "/usr/lib/python3/dist-packages/urllib3/connectionpool.py", line 560, in urlopen
    body=body, headers=headers)
  File "/usr/lib/python3/dist-packages/urllib3/connectionpool.py", line 379, in _make_request
    httplib_response = conn.getresponse()
  File "/usr/lib/python3.5/http/client.py", line 1197, in getresponse
    response.begin()
  File "/usr/lib/python3.5/http/client.py", line 297, in begin
    version, status, reason = self._read_status()
  File "/usr/lib/python3.5/http/client.py", line 258, in _read_status
    line = str(self.fp.readline(_MAXLINE + 1), "iso-8859-1")
  File "/usr/lib/python3.5/socket.py", line 575, in readinto
    return self._sock.recv_into(b)
KeyboardInterrupt
geislemx@sempro3128:~/middleware$ rm 201712092256_error.txt 
geislemx@sempro3128:~/middleware$ python3 testServiceServer.py > 201712092256_error.txt
Traceback (most recent call last):
  File "/usr/lib/python3/dist-packages/urllib3/connectionpool.py", line 377, in _make_request
    httplib_response = conn.getresponse(buffering=True)
TypeError: getresponse() got an unexpected keyword argument 'buffering'

During handling of the above exception, another exception occurred:

Traceback (most recent call last):
  File "/usr/lib/python3/dist-packages/urllib3/connectionpool.py", line 560, in urlopen
    body=body, headers=headers)
  File "/usr/lib/python3/dist-packages/urllib3/connectionpool.py", line 379, in _make_request
    httplib_response = conn.getresponse()
  File "/usr/lib/python3.5/http/client.py", line 1197, in getresponse
    response.begin()
  File "/usr/lib/python3.5/http/client.py", line 297, in begin
    version, status, reason = self._read_status()
  File "/usr/lib/python3.5/http/client.py", line 266, in _read_status
    raise RemoteDisconnected("Remote end closed connection without"
http.client.RemoteDisconnected: Remote end closed connection without response

During handling of the above exception, another exception occurred:

Traceback (most recent call last):
  File "/usr/lib/python3/dist-packages/requests/adapters.py", line 376, in send
    timeout=timeout
  File "/usr/lib/python3/dist-packages/urllib3/connectionpool.py", line 610, in urlopen
    _stacktrace=sys.exc_info()[2])
  File "/usr/lib/python3/dist-packages/urllib3/util/retry.py", line 247, in increment
    raise six.reraise(type(error), error, _stacktrace)
  File "/usr/lib/python3/dist-packages/six.py", line 685, in reraise
    raise value.with_traceback(tb)
  File "/usr/lib/python3/dist-packages/urllib3/connectionpool.py", line 560, in urlopen
    body=body, headers=headers)
  File "/usr/lib/python3/dist-packages/urllib3/connectionpool.py", line 379, in _make_request
    httplib_response = conn.getresponse()
  File "/usr/lib/python3.5/http/client.py", line 1197, in getresponse
    response.begin()
  File "/usr/lib/python3.5/http/client.py", line 297, in begin
    version, status, reason = self._read_status()
  File "/usr/lib/python3.5/http/client.py", line 266, in _read_status
    raise RemoteDisconnected("Remote end closed connection without"
requests.packages.urllib3.exceptions.ProtocolError: ('Connection aborted.', RemoteDisconnected('Remote end closed connection without response',))

During handling of the above exception, another exception occurred:

Traceback (most recent call last):
  File "/home/geislemx/middleware/classes/http_service.py", line 190, in call
    Response = self.__Session.send(ToSend)
  File "/usr/lib/python3/dist-packages/requests/sessions.py", line 576, in send
    r = adapter.send(request, **kwargs)
  File "/usr/lib/python3/dist-packages/requests/adapters.py", line 426, in send
    raise ConnectionError(err, request=request)
requests.exceptions.ConnectionError: ('Connection aborted.', RemoteDisconnected('Remote end closed connection without response',))

During handling of the above exception, another exception occurred:

Traceback (most recent call last):
  File "testServiceServer.py", line 25, in <module>
    print(Test.insertIntoDatabase(store, {'type':'document'}))
  File "/home/geislemx/middleware/classes/services.py", line 285, in insertIntoDatabase
    Response = self.__Database.insert(JSON, AdditionalParameter)
  File "/home/geislemx/middleware/classes/services.py", line 194, in insert
    raise e
  File "/home/geislemx/middleware/classes/services.py", line 191, in insert
    Response = self.__withOrWithoutBody(self.__Configuration['insert']['method'], Insert, self.__Insert, AdditionalParameter)
  File "/home/geislemx/middleware/classes/services.py", line 167, in __withOrWithoutBody
    Response = self.__withBody(ToDo, HTTPObject, AdditionalParameter)
  File "/home/geislemx/middleware/classes/services.py", line 149, in __withBody
    return HttpObject.call()
  File "/home/geislemx/middleware/classes/http_service.py", line 192, in call
    raise HttpServiceException(HttpServiceException.NO_CONECTION)
classes.http_service.HttpServiceException: 'The connection is not established'

During handling of the above exception, another exception occurred:

Traceback (most recent call last):
  File "/usr/lib/python3/dist-packages/urllib3/connectionpool.py", line 377, in _make_request
    httplib_response = conn.getresponse(buffering=True)
TypeError: getresponse() got an unexpected keyword argument 'buffering'

During handling of the above exception, another exception occurred:

Traceback (most recent call last):
  File "/usr/lib/python3/dist-packages/urllib3/connectionpool.py", line 560, in urlopen
    body=body, headers=headers)
  File "/usr/lib/python3/dist-packages/urllib3/connectionpool.py", line 379, in _make_request
    httplib_response = conn.getresponse()
  File "/usr/lib/python3.5/http/client.py", line 1197, in getresponse
    response.begin()
  File "/usr/lib/python3.5/http/client.py", line 297, in begin
    version, status, reason = self._read_status()
  File "/usr/lib/python3.5/http/client.py", line 266, in _read_status
    raise RemoteDisconnected("Remote end closed connection without"
http.client.RemoteDisconnected: Remote end closed connection without response

During handling of the above exception, another exception occurred:

Traceback (most recent call last):
  File "/usr/lib/python3/dist-packages/requests/adapters.py", line 376, in send
    timeout=timeout
  File "/usr/lib/python3/dist-packages/urllib3/connectionpool.py", line 610, in urlopen
    _stacktrace=sys.exc_info()[2])
  File "/usr/lib/python3/dist-packages/urllib3/util/retry.py", line 247, in increment
    raise six.reraise(type(error), error, _stacktrace)
  File "/usr/lib/python3/dist-packages/six.py", line 685, in reraise
    raise value.with_traceback(tb)
  File "/usr/lib/python3/dist-packages/urllib3/connectionpool.py", line 560, in urlopen
    body=body, headers=headers)
  File "/usr/lib/python3/dist-packages/urllib3/connectionpool.py", line 379, in _make_request
    httplib_response = conn.getresponse()
  File "/usr/lib/python3.5/http/client.py", line 1197, in getresponse
    response.begin()
  File "/usr/lib/python3.5/http/client.py", line 297, in begin
    version, status, reason = self._read_status()
  File "/usr/lib/python3.5/http/client.py", line 266, in _read_status
    raise RemoteDisconnected("Remote end closed connection without"
requests.packages.urllib3.exceptions.ProtocolError: ('Connection aborted.', RemoteDisconnected('Remote end closed connection without response',))

During handling of the above exception, another exception occurred:

Traceback (most recent call last):
  File "/home/geislemx/middleware/classes/http_service.py", line 190, in call
    Response = self.__Session.send(ToSend)
  File "/usr/lib/python3/dist-packages/requests/sessions.py", line 576, in send
    r = adapter.send(request, **kwargs)
  File "/usr/lib/python3/dist-packages/requests/adapters.py", line 426, in send
    raise ConnectionError(err, request=request)
requests.exceptions.ConnectionError: ('Connection aborted.', RemoteDisconnected('Remote end closed connection without response',))

During handling of the above exception, another exception occurred:

Traceback (most recent call last):
  File "testServiceServer.py", line 28, in <module>
    print(Test.insertIntoDatabase(store, {'type':'document'}))
  File "/home/geislemx/middleware/classes/services.py", line 285, in insertIntoDatabase
    Response = self.__Database.insert(JSON, AdditionalParameter)
  File "/home/geislemx/middleware/classes/services.py", line 194, in insert
    raise e
  File "/home/geislemx/middleware/classes/services.py", line 191, in insert
    Response = self.__withOrWithoutBody(self.__Configuration['insert']['method'], Insert, self.__Insert, AdditionalParameter)
  File "/home/geislemx/middleware/classes/services.py", line 167, in __withOrWithoutBody
    Response = self.__withBody(ToDo, HTTPObject, AdditionalParameter)
  File "/home/geislemx/middleware/classes/services.py", line 149, in __withBody
    return HttpObject.call()
  File "/home/geislemx/middleware/classes/http_service.py", line 192, in call
    raise HttpServiceException(HttpServiceException.NO_CONECTION)
classes.http_service.HttpServiceException: 'The connection is not established'



